Workbook

Sheet Hymnes
A1: Continent | B1: Drapeau | C1: Pays / territoire | D1: Statut | E1: Hymne (titre original) | F1: Titre en français | G1: Parolier(s) | H1: Compositeur(s) | I1: Date des paroles | J1: Date de la musique | K1: Date d'adoption | L1: Paroles originales | M1: Paroles translittérées | N1: Traduction française | O1: Paroles reproduites | P1: Source des paroles | Q1: Lien audio (Wikimedia Commons) | R1: Remarques | S1: Fichier audio direct (URL .mp3 / .ogg) | T1: Code ISO
A2: Afrique | B2: 🇿🇦 | C2: Afrique du Sud | D2: État souverain | E2: National Anthem of South Africa | F2: Hymne national d'Afrique du Sud | G2: Enoch Sontonga, C. J. Langenhoven (adaptation 1997) | H2: Enoch Sontonga, Marthinus Lourens de Villiers | I2: 1897 / 1918 / 1997 | J2: 1897 / 1921 | K2: 1997 | L2: Non reproduites ici : version officielle révisée après 1929 ou texte non vérifié — voir la source. | O2: Non | P2: https://fr.wikipedia.org/w/index.php?search=National+Anthem+of+South+Africa&title=Sp%C3%A9cial%3ARecherche&go=Go | Q2: https://commons.wikimedia.org/w/index.php?search=South+Africa+national+anthem&title=Special%3AMediaSearch&type=audio | R2: Hymne composite en 5 langues (xhosa, zoulou, sesotho, afrikaans, anglais) | T2: ZA
A3: Afrique | B3: 🇩🇿 | C3: Algérie | D3: État souverain | E3: قسماً (Qassaman) | F3: Nous jurons | G3: Moufdi Zakaria | H3: Mohamed Fawzi | I3: 1955 | J3: 1956 | K3: 1962 | L3: Non reproduites ici : texte postérieur à 1929, potentiellement protégé — voir la source. | O3: Non | P3: https://fr.wikipedia.org/w/index.php?search=Qassaman&title=Sp%C3%A9cial%3ARecherche&go=Go | Q3: https://commons.wikimedia.org/w/index.php?search=Algeria+national+anthem&title=Special%3AMediaSearch&type=audio | T3: DZ
A4: Afrique | B4: 🇦🇴 | C4: Angola | D4: État souverain | E4: Angola Avante! | F4: En avant, Angola ! | G4: Manuel Rui Alves Monteiro | H4: Rui Alberto Vieira Dias Mingas | I4: 1975 | J4: 1975 | K4: 1975 | L4: Non reproduites ici : texte postérieur à 1929, potentiellement protégé — voir la source. | O4: Non | P4: https://fr.wikipedia.org/w/index.php?search=Angola+Avante%21&title=Sp%C3%A9cial%3ARecherche&go=Go | Q4: https://commons.wikimedia.org/w/index.php?search=Angola+national+anthem&title=Special%3AMediaSearch&type=audio | T4: AO
A5: Afrique | B5: 🇧🇯 | C5: Bénin | D5: État souverain | E5: L'Aube nouvelle | F5: L'Aube nouvelle | G5: Gilbert Jean Dagnon | H5: Gilbert Jean Dagnon | I5: 1960 | J5: 1960 | K5: 1960 | L5: Non reproduites ici : texte postérieur à 1929, potentiellement protégé — voir la source. | O5: Non | P5: https://fr.wikipedia.org/w/index.php?search=L%27Aube+nouvelle&title=Sp%C3%A9cial%3ARecherche&go=Go | Q5: https://commons.wikimedia.org/w/index.php?search=Benin+national+anthem&title=Special%3AMediaSearch&type=audio | T5: BJ
A6: Afrique | B6: 🇧🇼 | C6: Botswana | D6: État souverain | E6: Fatshe leno la rona | F6: Béni soit ce noble pays | G6: Kgalemang Tumediso Motsete | H6: Kgalemang Tumediso Motsete | I6: 1962 | J6: 1962 | K6: 1966 | L6: Non reproduites ici : texte postérieur à 1929, potentiellement protégé — voir la source. | O6: Non | P6: https://fr.wikipedia.org/w/index.php?search=Fatshe+leno+la+rona&title=Sp%C3%A9cial%3ARecherche&go=Go | Q6: https://commons.wikimedia.org/w/index.php?search=Botswana+national+anthem&title=Special%3AMediaSearch&type=audio | T6: BW
A7: Afrique | B7: 🇧🇫 | C7: Burkina Faso | D7: État souverain | E7: Ditanyè | F7: Hymne de la victoire | G7: attribué à Thomas Sankara | H7: attribué à Thomas Sankara | I7: 1984 | J7: 1984 | K7: 1984 | L7: Non reproduites ici : texte postérieur à 1929, potentiellement protégé — voir la source. | O7: Non | P7: https://fr.wikipedia.org/w/index.php?search=Ditany%C3%A8&title=Sp%C3%A9cial%3ARecherche&go=Go | Q7: https://commons.wikimedia.org/w/index.php?search=Burkina+Faso+national+anthem&title=Special%3AMediaSearch&type=audio | T7: BF
A8: Afrique | B8: 🇧🇮 | C8: Burundi | D8: État souverain | E8: Burundi Bwacu | F8: Notre Burundi | G8: Jean-Baptiste Ntahokaja (collectif) | H8: Marc Barengayabo | I8: 1962 | J8: 1962 | K8: 1962 | L8: Non reproduites ici : texte postérieur à 1929, potentiellement protégé — voir la source. | O8: Non | P8: https://fr.wikipedia.org/w/index.php?search=Burundi+Bwacu&title=Sp%C3%A9cial%3ARecherche&go=Go | Q8: https://commons.wikimedia.org/w/index.php?search=Burundi+national+anthem&title=Special%3AMediaSearch&type=audio | T8: BI
A9: Afrique | B9: 🇨🇲 | C9: Cameroun | D9: État souverain | E9: Chant de ralliement | F9: Chant de ralliement | G9: René Djam Afame, Samuel Minkio Bamba, Moïse Nyatte Nko'o | H9: René Djam Afame | I9: 1928 (révisé 1970) | J9: 1928 | K9: 1957 (texte révisé 1970) | L9: Non reproduites ici : version officielle révisée après 1929 ou texte non vérifié — voir la source. | O9: Non | P9: https://fr.wikipedia.org/w/index.php?search=Chant+de+ralliement&title=Sp%C3%A9cial%3ARecherche&go=Go | Q9: https://commons.wikimedia.org/w/index.php?search=Cameroon+national+anthem&title=Special%3AMediaSearch&type=audio | R9: Texte officiel actuel : version révisée de 1970 | T9: CM
A10: Afrique | B10: 🇰🇲 | C10: Comores | D10: État souverain | E10: Udzima wa ya Masiwa | F10: L'Union des îles | G10: Said Hachim Sidi Abderemane | H10: Said Hachim Sidi Abderemane, Kamildine Abdallah | I10: 1978 | J10: 1978 | K10: 1978 | L10: Non reproduites ici : texte postérieur à 1929, potentiellement protégé — voir la source. | O10: Non | P10: https://fr.wikipedia.org/w/index.php?search=Udzima+wa+ya+Masiwa&title=Sp%C3%A9cial%3ARecherche&go=Go | Q10: https://commons.wikimedia.org/w/index.php?search=Comoros+national+anthem&title=Special%3AMediaSearch&type=audio | T10: KM
A11: Afrique | B11: 🇨🇬 | C11: Congo | D11: État souverain | E11: La Congolaise | F11: La Congolaise | G11: Jacques Tondra, Georges Kibanghi | H11: Jean Royer, Joseph Spadilière | I11: 1959 | J11: 1959 | K11: 1959 (rétabli 1991) | L11: Non reproduites ici : texte postérieur à 1929, potentiellement protégé — voir la source. | O11: Non | P11: https://fr.wikipedia.org/w/index.php?search=La+Congolaise&title=Sp%C3%A9cial%3ARecherche&go=Go | Q11: https://commons.wikimedia.org/w/index.php?search=Congo+national+anthem&title=Special%3AMediaSearch&type=audio | T11: CG
A12: Afrique | B12: 🇨🇩 | C12: Congo (Rép. dém.) | D12: État souverain | E12: Debout Congolais | F12: Debout, Congolais | G12: Joseph Lutumba | H12: Simon-Pierre Boka di Mpasi Londi | I12: 1960 | J12: 1960 | K12: 1960 (rétabli 1997) | L12: Non reproduites ici : texte postérieur à 1929, potentiellement protégé — voir la source. | O12: Non | P12: https://fr.wikipedia.org/w/index.php?search=Debout+Congolais&title=Sp%C3%A9cial%3ARecherche&go=Go | Q12: https://commons.wikimedia.org/w/index.php?search=DR+Congo+national+anthem&title=Special%3AMediaSearch&type=audio | T12: CD
A13: Afrique | B13: 🇨🇮 | C13: Côte d'Ivoire | D13: État souverain | E13: L'Abidjanaise | F13: L'Abidjanaise | G13: Mathieu Ekra, Joachim Bony, Pierre Marie Coty | H13: Pierre-Michel Pango | I13: 1960 | J13: 1960 | K13: 1960 | L13: Non reproduites ici : texte postérieur à 1929, potentiellement protégé — voir la source. | O13: Non | P13: https://fr.wikipedia.org/w/index.php?search=L%27Abidjanaise&title=Sp%C3%A9cial%3ARecherche&go=Go | Q13: https://commons.wikimedia.org/w/index.php?search=Ivory+Coast+national+anthem&title=Special%3AMediaSearch&type=audio | T13: CI
A14: Afrique | B14: 🇩🇯 | C14: Djibouti | D14: État souverain | E14: Jabuuti | F14: Djibouti | G14: Aden Elmi | H14: Abdi Robleh | I14: 1977 | J14: 1977 | K14: 1977 | L14: Non reproduites ici : texte postérieur à 1929, potentiellement protégé — voir la source. | O14: Non | P14: https://fr.wikipedia.org/w/index.php?search=Jabuuti&title=Sp%C3%A9cial%3ARecherche&go=Go | Q14: https://commons.wikimedia.org/w/index.php?search=Djibouti+national+anthem&title=Special%3AMediaSearch&type=audio | T14: DJ
A15: Afrique | B15: 🇪🇬 | C15: Égypte | D15: État souverain | E15: بلادي بلادي بلادي (Bilady, Bilady, Bilady) | F15: Ma patrie, ma patrie, ma patrie | G15: Mohamed Younis al-Qadi | H15: Sayed Darwish | I15: 1923 | J15: 1923 | K15: 1979 | L15: (Refrain) بلادي بلادي بلادي لكِ حبي وفؤادي بلادي بلادي بلادي لكِ حبي وفؤادي مصر يا أم البلاد أنتِ غايتي والمراد وعلى كل العباد كم لنيلك من أيادي | M15: (Refrain) Biladi, biladi, biladi, laki hubbi wa fu'adi. Biladi, biladi, biladi, laki hubbi wa fu'adi. Misr ya umm al-bilad, inti ghayati wal-murad, wa 'ala kull il-'ibad kam li-Nilik min ayadi. | N15: (Refrain) Ma patrie, ma patrie, ma patrie, à toi mon amour et mon cœur. Ma patrie, ma patrie, ma patrie, à toi mon amour et mon cœur. Égypte, mère de tous les pays, tu es mon espoir et mon ambition, et sur tous les peuples ton Nil a répandu tant de bienfaits. | O15: Oui | P15: Domaine public (texte de 1923) ; vérification : https://fr.wikipedia.org/w/index.php?search=Bilady%2C+Bilady%2C+Bilady&title=Sp%C3%A9cial%3ARecherche&go=Go | Q15: https://commons.wikimedia.org/w/index.php?search=Egypt+national+anthem&title=Special%3AMediaSearch&type=audio | R15: On chante le refrain et la 1re strophe | T15: EG
A16: Afrique | B16: 🇪🇷 | C16: Érythrée | D16: État souverain | E16: ኤርትራ ኤርትራ ኤርትራ (Ertra, Ertra, Ertra) | F16: Érythrée, Érythrée, Érythrée | G16: Solomon Tsehaye Beraki | H16: Isaac Abraham Meharezghi, Aron Tekle Tesfatsion | I16: 1986 | J16: 1986 | K16: 1993 | L16: Non reproduites ici : texte postérieur à 1929, potentiellement protégé — voir la source. | O16: Non | P16: https://fr.wikipedia.org/w/index.php?search=Ertra%2C+Ertra%2C+Ertra&title=Sp%C3%A9cial%3ARecherche&go=Go | Q16: https://commons.wikimedia.org/w/index.php?search=Eritrea+national+anthem&title=Special%3AMediaSearch&type=audio | T16: ER
A17: Afrique | B17: 🇸🇿 | C17: Eswatini | D17: État souverain | E17: Nkulunkulu Mnikati wetibusiso temaSwati | F17: Ô Dieu, dispensateur des bénédictions des Swazis | G17: Andrease Enoke Fanyana Simelane | H17: David Kenneth Rycroft | I17: 1968 | J17: 1968 | K17: 1968 | L17: Non reproduites ici : texte postérieur à 1929, potentiellement protégé — voir la source. | O17: Non | P17: https://fr.wikipedia.org/w/index.php?search=Nkulunkulu+Mnikati+wetibusiso+temaSwati&title=Sp%C3%A9cial%3ARecherche&go=Go | Q17: https://commons.wikimedia.org/w/index.php?search=Eswatini+national+anthem&title=Special%3AMediaSearch&type=audio | T17: SZ
A18: Afrique | B18: 🇪🇹 | C18: Éthiopie | D18: État souverain | E18: ወደፊት ገስግሺ ውድ እናት ኢትዮጵያ (Wedefit Gesgeshi Widd Innat Ityopp'ya) | F18: En avant, chère mère Éthiopie | G18: Dereje Melaku Mengesha | H18: Solomon Lulu Mitiku | I18: 1992 | J18: 1992 | K18: 1992 | L18: Non reproduites ici : texte postérieur à 1929, potentiellement protégé — voir la source. | O18: Non | P18: https://fr.wikipedia.org/w/index.php?search=Wedefit+Gesgeshi+Widd+Innat+Ityopp%27ya&title=Sp%C3%A9cial%3ARecherche&go=Go | Q18: https://commons.wikimedia.org/w/index.php?search=Ethiopia+national+anthem&title=Special%3AMediaSearch&type=audio | T18: ET
A19: Afrique | B19: 🇬🇦 | C19: Gabon | D19: État souverain | E19: La Concorde | F19: La Concorde | G19: Georges Aleka Damas | H19: Georges Aleka Damas | I19: 1960 | J19: 1960 | K19: 1960 | L19: Non reproduites ici : texte postérieur à 1929, potentiellement protégé — voir la source. | O19: Non | P19: https://fr.wikipedia.org/w/index.php?search=La+Concorde&title=Sp%C3%A9cial%3ARecherche&go=Go | Q19: https://commons.wikimedia.org/w/index.php?search=Gabon+national+anthem&title=Special%3AMediaSearch&type=audio | T19: GA
A20: Afrique | B20: 🇬🇲 | C20: Gambie | D20: État souverain | E20: For The Gambia, Our Homeland | F20: Pour la Gambie, notre patrie | G20: Virginia Julie Howe | H20: Jeremy Frederick Howe (sur un air traditionnel mandingue) | I20: 1965 | J20: 1965 | K20: 1965 | L20: Non reproduites ici : texte postérieur à 1929, potentiellement protégé — voir la source. | O20: Non | P20: https://fr.wikipedia.org/w/index.php?search=For+The+Gambia%2C+Our+Homeland&title=Sp%C3%A9cial%3ARecherche&go=Go | Q20: https://commons.wikimedia.org/w/index.php?search=Gambia+national+anthem&title=Special%3AMediaSearch&type=audio | T20: GM
A21: Afrique | B21: 🇬🇭 | C21: Ghana | D21: État souverain | E21: God Bless Our Homeland Ghana | F21: Dieu bénisse notre patrie, le Ghana | G21: Michael Kwame Gbordzoe | H21: Philip Gbeho | I21: 1966 | J21: 1957 | K21: 1957 (paroles 1966) | L21: Non reproduites ici : texte postérieur à 1929, potentiellement protégé — voir la source. | O21: Non | P21: https://fr.wikipedia.org/w/index.php?search=God+Bless+Our+Homeland+Ghana&title=Sp%C3%A9cial%3ARecherche&go=Go | Q21: https://commons.wikimedia.org/w/index.php?search=Ghana+national+anthem&title=Special%3AMediaSearch&type=audio | T21: GH
A22: Afrique | B22: 🇬🇳 | C22: Guinée | D22: État souverain | E22: Liberté | F22: Liberté | G22: Jean Celestin Traoré | H22: Fodéba Keïta (sur l'air « Alpha Yaya ») | I22: 1958 | J22: 1958 | K22: 1958 | L22: Non reproduites ici : texte postérieur à 1929, potentiellement protégé — voir la source. | O22: Non | P22: https://fr.wikipedia.org/w/index.php?search=Libert%C3%A9&title=Sp%C3%A9cial%3ARecherche&go=Go | Q22: https://commons.wikimedia.org/w/index.php?search=Guinea+national+anthem&title=Special%3AMediaSearch&type=audio | T22: GN
A23: Afrique | B23: 🇬🇶 | C23: Guinée équatoriale | D23: État souverain | E23: Caminemos pisando las sendas | F23: Marchons sur les sentiers | G23: Atanasio Ndongo Miyone | H23: Ramírez Ortiz | I23: 1968 | J23: 1968 | K23: 1968 | L23: Non reproduites ici : texte postérieur à 1929, potentiellement protégé — voir la source. | O23: Non | P23: https://fr.wikipedia.org/w/index.php?search=Caminemos+pisando+las+sendas&title=Sp%C3%A9cial%3ARecherche&go=Go | Q23: https://commons.wikimedia.org/w/index.php?search=Equatorial+Guinea+national+anthem&title=Special%3AMediaSearch&type=audio | T23: GQ
A24: Afrique | B24: 🇬🇼 | C24: Guinée-Bissau | D24: État souverain | E24: Esta é a Nossa Pátria Bem Amada | F24: Voici notre patrie bien-aimée | G24: Amílcar Cabral | H24: Xiao He | I24: 1963 | J24: 1963 | K24: 1974 | L24: Non reproduites ici : texte postérieur à 1929, potentiellement protégé — voir la source. | O24: Non | P24: https://fr.wikipedia.org/w/index.php?search=Esta+%C3%A9+a+Nossa+P%C3%A1tria+Bem+Amada&title=Sp%C3%A9cial%3ARecherche&go=Go | Q24: https://commons.wikimedia.org/w/index.php?search=Guinea-Bissau+national+anthem&title=Special%3AMediaSearch&type=audio | T24: GW
A25: Afrique | B25: 🇲🇺 | C25: Île Maurice | D25: État souverain | E25: Motherland | F25: Mère patrie | G25: Jean-Georges Prosper | H25: Philippe Gentil | I25: 1968 | J25: 1968 | K25: 1968 | L25: Non reproduites ici : texte postérieur à 1929, potentiellement protégé — voir la source. | O25: Non | P25: https://fr.wikipedia.org/w/index.php?search=Motherland&title=Sp%C3%A9cial%3ARecherche&go=Go | Q25: https://commons.wikimedia.org/w/index.php?search=Mauritius+national+anthem&title=Special%3AMediaSearch&type=audio | T25: MU
A26: Afrique | B26: 🇨🇻 | C26: Îles du Cap-Vert | D26: État souverain | E26: Cântico da Liberdade | F26: Cantique de la liberté | G26: Amílcar Spencer Lopes | H26: Adalberto Higino Tavares Silva | I26: 1996 | J26: 1996 | K26: 1996 | L26: Non reproduites ici : texte postérieur à 1929, potentiellement protégé — voir la source. | O26: Non | P26: https://fr.wikipedia.org/w/index.php?search=C%C3%A2ntico+da+Liberdade&title=Sp%C3%A9cial%3ARecherche&go=Go | Q26: https://commons.wikimedia.org/w/index.php?search=Cape+Verde+national+anthem&title=Special%3AMediaSearch&type=audio | T26: CV
A27: Afrique | B27: 🇰🇪 | C27: Kenya | D27: État souverain | E27: Ee Mungu Nguvu Yetu | F27: Ô Dieu de toute création | G27: commission nationale | H27: mélodie traditionnelle pokomo | I27: 1963 | J27: traditionnelle | K27: 1963 | L27: Non reproduites ici : texte postérieur à 1929, potentiellement protégé — voir la source. | O27: Non | P27: https://fr.wikipedia.org/w/index.php?search=Ee+Mungu+Nguvu+Yetu&title=Sp%C3%A9cial%3ARecherche&go=Go | Q27: https://commons.wikimedia.org/w/index.php?search=Kenya+national+anthem&title=Special%3AMediaSearch&type=audio | T27: KE
A28: Afrique | B28: 🇱🇸 | C28: Lesotho | D28: État souverain | E28: Lesotho Fatše La Bo-ntat'a Rona | F28: Lesotho, terre de nos pères | G28: François Coillard | H28: Ferdinand-Samuel Laur | I28: 1869 | J28: 1823 | K28: 1967 | L28: Lesotho fatše la bo-ntat'a rona, Har'a mafatše le letle ke lona. Ke moo re hlahileng, Ke moo re holileng, Rea le rata. Molimo aku boloke Lesotho, U felise lintoa le matšoenyeho. Oho fatše lena, La bo-ntat'a rona, Le be le khotso. | M28: — (écriture latine) | N28: Lesotho, terre de nos pères, de tous les pays, tu es le plus beau. C'est là que nous sommes nés, c'est là que nous avons grandi, nous t'aimons. Dieu, protège le Lesotho, mets fin aux guerres et aux tourments. Ô cette terre, terre de nos pères, qu'elle soit en paix. | O28: Oui | P28: Domaine public (texte de 1869) ; vérification : https://fr.wikipedia.org/w/index.php?search=Lesotho+Fat%C5%A1e+La+Bo-ntat%27a+Rona&title=Sp%C3%A9cial%3ARecherche&go=Go | Q28: https://commons.wikimedia.org/w/index.php?search=Lesotho+national+anthem&title=Special%3AMediaSearch&type=audio | T28: LS
A29: Afrique | B29: 🇱🇷 | C29: Liberia | D29: État souverain | E29: All Hail, Liberia, Hail! | F29: Salut, Liberia, salut ! | G29: Daniel Bashiel Warner | H29: Olmstead Luca | I29: 1847 | J29: 1860 | K29: 1847 | L29: All hail, Liberia, hail! (All hail!) All hail, Liberia, hail! (All hail!) This glorious land of liberty Shall long be ours. Though new her name, Green be her fame, And mighty be her powers, And mighty be her powers. In joy and gladness With our hearts united, We'll shout the freedom Of a race benighted, Long live Liberia, happy land! A home of glorious liberty, By God's command! A home of glorious liberty, By God's command! | M29: — (écriture latine) | N29: Salut, Liberia, salut ! (Salut !) Salut, Liberia, salut ! (Salut !) Cette glorieuse terre de liberté sera longtemps nôtre. Bien que son nom soit nouveau, que sa renommée soit florissante et sa puissance grande, et sa puissance grande. Dans la joie et l'allégresse, les cœurs unis, nous proclamerons la liberté d'une race longtemps plongée dans les ténèbres. Vive le Liberia, terre heureuse ! Demeure d'une glorieuse liberté, par la volonté de Dieu ! Demeure d'une glorieuse liberté, par la volonté de Dieu ! | O29: Oui | P29: Domaine public (texte de 1847) ; vérification : https://fr.wikipedia.org/w/index.php?search=All+Hail%2C+Liberia%2C+Hail%21&title=Sp%C3%A9cial%3ARecherche&go=Go | Q29: https://commons.wikimedia.org/w/index.php?search=Liberia+national+anthem&title=Special%3AMediaSearch&type=audio | T29: LR
A30: Afrique | B30: 🇱🇾 | C30: Libye | D30: État souverain | E30: ليبيا ليبيا ليبيا (Libya, Libya, Libya) | F30: Libye, Libye, Libye | G30: Al Bashir Al Arebi | H30: Mohammed Abdel Wahab | I30: 1951 | J30: 1951 | K30: 1951 (rétabli 2011) | L30: Non reproduites ici : texte postérieur à 1929, potentiellement protégé — voir la source. | O30: Non | P30: https://fr.wikipedia.org/w/index.php?search=Libya%2C+Libya%2C+Libya&title=Sp%C3%A9cial%3ARecherche&go=Go | Q30: https://commons.wikimedia.org/w/index.php?search=Libya+national+anthem&title=Special%3AMediaSearch&type=audio | T30: LY
A31: Afrique | B31: 🇲🇬 | C31: Madagascar | D31: État souverain | E31: Ry Tanindrazanay malala ô! | F31: Ô notre chère patrie | G31: Pasteur Rahajason | H31: Norbert Raharisoa | I31: 1958 | J31: 1958 | K31: 1959 | L31: Non reproduites ici : texte postérieur à 1929, potentiellement protégé — voir la source. | O31: Non | P31: https://fr.wikipedia.org/w/index.php?search=Ry+Tanindrazanay+malala+%C3%B4%21&title=Sp%C3%A9cial%3ARecherche&go=Go | Q31: https://commons.wikimedia.org/w/index.php?search=Madagascar+national+anthem&title=Special%3AMediaSearch&type=audio | T31: MG
A32: Afrique | B32: 🇲🇼 | C32: Malawi | D32: État souverain | E32: Mlungu dalitsani Malaŵi | F32: Ô Dieu, bénis notre terre du Malawi | G32: Michael-Fredrick Paul Sauka | H32: Michael-Fredrick Paul Sauka | I32: 1964 | J32: 1964 | K32: 1964 | L32: Non reproduites ici : texte postérieur à 1929, potentiellement protégé — voir la source. | O32: Non | P32: https://fr.wikipedia.org/w/index.php?search=Mlungu+dalitsani+Mala%C5%B5i&title=Sp%C3%A9cial%3ARecherche&go=Go | Q32: https://commons.wikimedia.org/w/index.php?search=Malawi+national+anthem&title=Special%3AMediaSearch&type=audio | T32: MW
A33: Afrique | B33: 🇲🇱 | C33: Mali | D33: État souverain | E33: Le Mali | F33: Le Mali | G33: Seydou Badian Kouyaté | H33: Banzoumana Sissoko | I33: 1962 | J33: 1962 | K33: 1962 | L33: Non reproduites ici : texte postérieur à 1929, potentiellement protégé — voir la source. | O33: Non | P33: https://fr.wikipedia.org/w/index.php?search=Le+Mali&title=Sp%C3%A9cial%3ARecherche&go=Go | Q33: https://commons.wikimedia.org/w/index.php?search=Mali+national+anthem&title=Special%3AMediaSearch&type=audio | T33: ML
A34: Afrique | B34: 🇲🇦 | C34: Maroc | D34: État souverain | E34: النشيد الوطني المغربي (Hymne chérifien) | F34: Hymne chérifien | G34: Ali Squalli Houssaini | H34: Léo Morgan | I34: 1970 | J34: 1956 | K34: 1956 (paroles 1970) | L34: Non reproduites ici : texte postérieur à 1929, potentiellement protégé — voir la source. | O34: Non | P34: https://fr.wikipedia.org/w/index.php?search=Hymne+ch%C3%A9rifien&title=Sp%C3%A9cial%3ARecherche&go=Go | Q34: https://commons.wikimedia.org/w/index.php?search=Morocco+national+anthem&title=Special%3AMediaSearch&type=audio | T34: MA
A35: Afrique | B35: 🇲🇷 | C35: Mauritanie | D35: État souverain | E35: بلادِ الإباءِ (Bilādu-l-ʾibāʾi) | F35: Pays des fiers | G35: collectif | H35: Rajeh Daoud | I35: 2017 | J35: 2017 | K35: 2017 | L35: Non reproduites ici : texte postérieur à 1929, potentiellement protégé — voir la source. | O35: Non | P35: https://fr.wikipedia.org/w/index.php?search=Bil%C4%81du-l-%CA%BEib%C4%81%CA%BEi&title=Sp%C3%A9cial%3ARecherche&go=Go | Q35: https://commons.wikimedia.org/w/index.php?search=Mauritania+national+anthem&title=Special%3AMediaSearch&type=audio | R35: Remplace l'hymne de 1960 (à vérifier) | T35: MR
A36: Afrique | B36: 🇾🇹 | C36: Mayotte | D36: Territoire / dépendance (France) | E36: La Marseillaise | F36: La Marseillaise | G36: Claude Joseph Rouget de Lisle | H36: Claude Joseph Rouget de Lisle | I36: 1792 | J36: 1792 | K36: 1795 (définitivement 1879) | L36: Allons enfants de la Patrie, Le jour de gloire est arrivé ! Contre nous de la tyrannie L'étendard sanglant est levé, (bis) Entendez-vous dans les campagnes Mugir ces féroces soldats ? Ils viennent jusque dans vos bras Égorger vos fils, vos compagnes ! Aux armes, citoyens, Formez vos bataillons, Marchons, marchons ! Qu'un sang impur Abreuve nos sillons ! | M36: — (écriture latine) | N36: — (texte original en français) | O36: Oui | P36: Domaine public (texte de 1792) ; vérification : https://fr.wikipedia.org/w/index.php?search=La+Marseillaise&title=Sp%C3%A9cial%3ARecherche&go=Go | Q36: https://commons.wikimedia.org/w/index.php?search=France+national+anthem&title=Special%3AMediaSearch&type=audio | R36: Département et région d'outre-mer français — utilise l'hymne de : France | T36: YT
A37: Afrique | B37: 🇲🇿 | C37: Mozambique | D37: État souverain | E37: Pátria Amada | F37: Patrie bien-aimée | G37: Salomão J. Manhiça (collectif) | H37: Justino Sigaulane Chemane | I37: 2002 | J37: 2002 | K37: 2002 | L37: Non reproduites ici : texte postérieur à 1929, potentiellement protégé — voir la source. | O37: Non | P37: https://fr.wikipedia.org/w/index.php?search=P%C3%A1tria+Amada&title=Sp%C3%A9cial%3ARecherche&go=Go | Q37: https://commons.wikimedia.org/w/index.php?search=Mozambique+national+anthem&title=Special%3AMediaSearch&type=audio | T37: MZ
A38: Afrique | B38: 🇳🇦 | C38: Namibie | D38: État souverain | E38: Namibia, Land of the Brave | F38: Namibie, terre des braves | G38: Axali Doëseb | H38: Axali Doëseb | I38: 1991 | J38: 1991 | K38: 1991 | L38: Non reproduites ici : texte postérieur à 1929, potentiellement protégé — voir la source. | O38: Non | P38: https://fr.wikipedia.org/w/index.php?search=Namibia%2C+Land+of+the+Brave&title=Sp%C3%A9cial%3ARecherche&go=Go | Q38: https://commons.wikimedia.org/w/index.php?search=Namibia+national+anthem&title=Special%3AMediaSearch&type=audio | T38: NA
A39: Afrique | B39: 🇳🇪 | C39: Niger | D39: État souverain | E39: L'Honneur de la Patrie | F39: L'Honneur de la Patrie | G39: collectif | H39: collectif | I39: 2023 | J39: 2023 | K39: 2023 | L39: Non reproduites ici : texte postérieur à 1929, potentiellement protégé — voir la source. | O39: Non | P39: https://fr.wikipedia.org/w/index.php?search=L%27Honneur+de+la+Patrie&title=Sp%C3%A9cial%3ARecherche&go=Go | Q39: https://commons.wikimedia.org/w/index.php?search=Niger+national+anthem&title=Special%3AMediaSearch&type=audio | R39: Remplace « La Nigérienne » (1961) (à vérifier) | T39: NE
A40: Afrique | B40: 🇳🇬 | C40: Nigéria | D40: État souverain | E40: Nigeria, We Hail Thee | F40: Nigeria, nous te saluons | G40: Lillian Jean Williams | H40: Frances Berda | I40: 1960 | J40: 1960 | K40: 1960 (rétabli en 2024) | L40: Non reproduites ici : texte postérieur à 1929, potentiellement protégé — voir la source. | O40: Non | P40: https://fr.wikipedia.org/w/index.php?search=Nigeria%2C+We+Hail+Thee&title=Sp%C3%A9cial%3ARecherche&go=Go | Q40: https://commons.wikimedia.org/w/index.php?search=Nigeria+national+anthem&title=Special%3AMediaSearch&type=audio | R40: Remplace « Arise, O Compatriots » (1978-2024) | T40: NG
...

Sheet Synthèse
A1: Continent | B1: Nombre de lignes | C1: dont États souverains | D1: Paroles reproduites | E1: Paroles non reproduites | F1: Hymnes sans paroles
A2: Afrique | B2: =COUNTIF(Hymnes!$A$2:$A$250,A2) -> 60 | C2: =COUNTIFS(Hymnes!$A$2:$A$250,A2,Hymnes!$D$2:$D$250,"État souverain") -> 54 | D2: =COUNTIFS(Hymnes!$A$2:$A$250,A2,Hymnes!$O$2:$O$250,"Oui") -> 8 | E2: =COUNTIFS(Hymnes!$A$2:$A$250,A2,Hymnes!$O$2:$O$250,"Non") -> 52 | F2: =COUNTIFS(Hymnes!$A$2:$A$250,A2,Hymnes!$O$2:$O$250,"Sans objet") -> 0
A3: Amérique du Nord | B3: =COUNTIF(Hymnes!$A$2:$A$250,A3) -> 42 | C3: =COUNTIFS(Hymnes!$A$2:$A$250,A3,Hymnes!$D$2:$D$250,"État souverain") -> 23 | D3: =COUNTIFS(Hymnes!$A$2:$A$250,A3,Hymnes!$O$2:$O$250,"Oui") -> 24 | E3: =COUNTIFS(Hymnes!$A$2:$A$250,A3,Hymnes!$O$2:$O$250,"Non") -> 18 | F3: =COUNTIFS(Hymnes!$A$2:$A$250,A3,Hymnes!$O$2:$O$250,"Sans objet") -> 0
A4: Amérique du Sud | B4: =COUNTIF(Hymnes!$A$2:$A$250,A4) -> 16 | C4: =COUNTIFS(Hymnes!$A$2:$A$250,A4,Hymnes!$D$2:$D$250,"État souverain") -> 12 | D4: =COUNTIFS(Hymnes!$A$2:$A$250,A4,Hymnes!$O$2:$O$250,"Oui") -> 14 | E4: =COUNTIFS(Hymnes!$A$2:$A$250,A4,Hymnes!$O$2:$O$250,"Non") -> 2 | F4: =COUNTIFS(Hymnes!$A$2:$A$250,A4,Hymnes!$O$2:$O$250,"Sans objet") -> 0
A5: Asie | B5: =COUNTIF(Hymnes!$A$2:$A$250,A5) -> 50 | C5: =COUNTIFS(Hymnes!$A$2:$A$250,A5,Hymnes!$D$2:$D$250,"État souverain") -> 46 | D5: =COUNTIFS(Hymnes!$A$2:$A$250,A5,Hymnes!$O$2:$O$250,"Oui") -> 11 | E5: =COUNTIFS(Hymnes!$A$2:$A$250,A5,Hymnes!$O$2:$O$250,"Non") -> 38 | F5: =COUNTIFS(Hymnes!$A$2:$A$250,A5,Hymnes!$O$2:$O$250,"Sans objet") -> 1
A6: Europe | B6: =COUNTIF(Hymnes!$A$2:$A$250,A6) -> 53 | C6: =COUNTIFS(Hymnes!$A$2:$A$250,A6,Hymnes!$D$2:$D$250,"État souverain") -> 45 | D6: =COUNTIFS(Hymnes!$A$2:$A$250,A6,Hymnes!$O$2:$O$250,"Oui") -> 38 | E6: =COUNTIFS(Hymnes!$A$2:$A$250,A6,Hymnes!$O$2:$O$250,"Non") -> 11 | F6: =COUNTIFS(Hymnes!$A$2:$A$250,A6,Hymnes!$O$2:$O$250,"Sans objet") -> 4
A7: Océanie | B7: =COUNTIF(Hymnes!$A$2:$A$250,A7) -> 28 | C7: =COUNTIFS(Hymnes!$A$2:$A$250,A7,Hymnes!$D$2:$D$250,"État souverain") -> 14 | D7: =COUNTIFS(Hymnes!$A$2:$A$250,A7,Hymnes!$O$2:$O$250,"Oui") -> 12 | E7: =COUNTIFS(Hymnes!$A$2:$A$250,A7,Hymnes!$O$2:$O$250,"Non") -> 16 | F7: =COUNTIFS(Hymnes!$A$2:$A$250,A7,Hymnes!$O$2:$O$250,"Sans objet") -> 0
A8: Total | B8: =SUM(B2:B7) -> 249 | C8: =SUM(C2:C7) -> 194 | D8: =SUM(D2:D7) -> 107 | E8: =SUM(E2:E7) -> 137 | F8: =SUM(F2:F7) -> 5

Sheet Notes
A1: Méthode et limites
A2: Périmètre | B2: 249 pays et territoires (référentiel mledoze/countries) ; l'Antarctique est exclu : il ne relève d'aucune souveraineté, seulement de revendications gelées par le traité sur l'Antarctique. Les territoires sans hymne propre reprennent l'hymne de l'État de rattachement (voir colonne Remarques).
A3: Continents | B3: Rattachement continental du référentiel ; les pays transcontinentaux (Russie, Turquie, Kazakhstan…) sont classés selon le premier continent indiqué. Les îles subantarctiques suivent la classification M49 de l'ONU : Terres australes françaises en Afrique, îles Heard-et-MacDonald en Océanie, île Bouvet et Géorgie du Sud en Amérique du Sud.
A4: Drapeau | B4: Emoji drapeau Unicode. S'affiche en couleur sur Mac, mobile et la plupart des navigateurs ; Excel sous Windows peut n'afficher que les deux lettres du code pays.
A5: Paroles | B5: Texte intégral reproduit uniquement pour les paroles écrites avant 1929 (domaine public), dans la version officiellement chantée. Pour les autres, la colonne « Source des paroles » renvoie vers Wikipédia.
A6: Translittération | B6: Fournie pour les écritures non latines (grec, cyrillique, arménien, japonais, coréen, chinois, devanagari, bengali, hébreu, arabe).
A7: Traductions | B7: Traductions françaises de travail, établies pour ce tableau ; à relire avant toute publication. Quand une version française officielle existe (Belgique, Suisse, Canada, Haïti), elle est indiquée.
A8: Audio | B8: Les fichiers ne pouvaient pas être téléchargés depuis l'environnement de travail : chaque lien ouvre la recherche audio de Wikimedia Commons (enregistrements libres, souvent .ogg ou .mp3) pour l'hymne concerné.
A9: Audio direct | B9: Colonne « Fichier audio direct » : collez-y l'URL d'un fichier .mp3 ou .ogg (par ex. un lien upload.wikimedia.org). Le site Planète Hymnes affiche alors un lecteur intégré dans la fiche.
A10: Code ISO | B10: Code ISO 3166-1 alpha-2 utilisé par le site pour placer chaque ligne sur la carte. À ne pas modifier.
A11: Fiabilité | B11: Données établies à partir des connaissances disponibles à mi-2026 ; les mentions « à vérifier » signalent les informations les moins sûres. Les hymnes changent parfois (ex. Nigeria 2024, Niger 2023).
